<?xml version="1.0"?>
<robot name="go2d1_description">
  <material name="black">
    <color rgba="0.0 0.0 0.0 1.0" />
  </material>
  <material name="blue">
    <color rgba="0.0 0.0 0.8 1.0" />
  </material>
  <material name="green">
    <color rgba="0.0 0.8 0.0 1.0" />
  </material>
  <material name="grey">
    <color rgba="0.2 0.2 0.2 1.0" />
  </material>
  <material name="silver">
    <color rgba="0.9137254901960784 0.9137254901960784 0.8470588235294118 1.0" />
  </material>
  <material name="orange">
    <!-- <color rgba="1.0 0.4235294117647059 0.0392156862745098 1.0"/> -->
    <color rgba="0.12 0.15 0.2 1.0" />
  </material>
  <material name="brown">
    <color rgba="0.8705882352941177 0.8117647058823529 0.7647058823529411 1.0" />
  </material>
  <material name="red">
    <color rgba="0.8 0.0 0.0 1.0" />
  </material>
  <material name="white">
    <color rgba="1.0 1.0 1.0 1.0" />
  </material>


  <!-- Start of Go2 Links and Joints -->
  <link name="base">
    <visual>
      <origin rpy="0 0 0" xyz="0 0 0" />
      <geometry>
        <box size="0.001 0.001 0.001" />
      </geometry>
    </visual>
  </link>
  <joint name="floating_base" type="fixed" dont_collapse="true">
    <origin rpy="0 0 0" xyz="0 0 0" />
    <parent link="base" />
    <child link="trunk" />
  </joint>
  <link name="trunk">
    <visual>
      <origin rpy="0 0 0" xyz="0 0 0" />
      <geometry>
        <mesh filename="../meshes/trunk.dae"
          scale="1 1 1" />
      </geometry>
      <material name="orange" />
    </visual>
    <collision>
      <origin rpy="0 0 0" xyz="0 0 0" />
      <geometry>
        <box size="0.3762 0.0935 0.114" />
      </geometry>
    </collision>
    <!-- <collision>
            <origin rpy="0 0 0" xyz="0 0 0"/>
            <geometry>
                <mesh filename="../meshes/trunk.dae" scale="1 1
    1"/>
            </geometry>
        </collision> -->
    <inertial>
      <origin rpy="0 0 0" xyz="0.021112 0 -0.005366" />
      <mass value="25" />
      <inertia 
        ixx="0.02448"
        ixy="0.00012166"
        ixz="0.0014849"
        iyy="0.098077"
        iyz="-3.12E-05"
        izz="0.107" />
    </inertial>
  </link>
  <joint name="imu_joint" type="fixed">
    <parent link="trunk" />
    <child link="imu_link" />
    <origin rpy="0 0 0" xyz="0 0 0" />
  </joint>
  <link name="imu_link">
    <inertial>
      <mass value="0.001" />
      <origin rpy="0 0 0" xyz="0 0 0" />
      <inertia ixx="0.0001" ixy="0" ixz="0" iyy="0.000001" iyz="0" izz="0.0001" />
    </inertial>
    <visual>
      <origin rpy="0 0 0" xyz="0 0 0" />
      <geometry>
        <box size="0.001 0.001 0.001" />
      </geometry>
      <material name="red" />
    </visual>
    <!-- <collision>
      <origin rpy="0 0 0" xyz="0 0 0"/>
      <geometry>
        <box size=".001 .001 .001"/>
      </geometry>
    </collision> -->
  </link>
  <joint name="FR_hip_joint" type="revolute">
    <origin rpy="0 0 0" xyz="0.1934 -0.0465 0" />
    <parent link="trunk" />
    <child link="FR_hip" />
    <axis xyz="1 0 0" />
    <dynamics damping="0" friction="0" />
    <limit effort="23.7" lower="-1.0472" upper="1.0472" velocity="30.1" />
  </joint>
  <link name="FR_hip">
    <visual>
      <origin rpy="3.1415 0 0" xyz="0 0 0" />
      <geometry>
        <mesh filename="../meshes/hip.dae"
          scale="1 1 1" />
      </geometry>
      <material name="orange" />
    </visual>
    <!-- <collision>
      <origin rpy="1.5707963267948966 0 0" xyz="0 -0.12675 0"/>
      <geometry>
        <cylinder length="0.04" radius="0.09"/>
      </geometry>
    </collision> -->
    <inertial>
      <origin rpy="0 0 0" xyz="-0.0054 -0.00194 -0.000105" />
      <mass value="0.678" />
      <inertia 
        ixx="0.00048"
        ixy="3.01E-06"
        ixz="1.11E-06"
        iyy="0.000884"
        iyz="1.42E-06"
        izz="0.000596" />
    </inertial>
  </link>
  <joint name="FR_thigh_joint" type="revolute">
    <origin rpy="0 0 0" xyz="0 -0.0955 0" />
    <parent link="FR_hip" />
    <child link="FR_thigh" />
    <axis xyz="0 1 0" />
    <dynamics damping="0" friction="0" />
    <limit effort="23.7" lower="-1.5708" upper="3.4907" velocity="30.1" />
  </joint>
  <link name="FR_thigh">
    <visual>
      <origin rpy="0 0 0" xyz="0 0 0" />
      <geometry>
        <mesh
          filename="../meshes/thigh_mirror.dae"
          scale="1 1 1" />
      </geometry>
      <material name="orange" />
    </visual>
    <collision>
      <origin rpy="0 1.5707963267948966 0" xyz="0 0 -0.1065" />
      <geometry>
        <box size="0.213 0.0245 0.034" />
      </geometry>
    </collision>
    <inertial>
      <origin rpy="0 0 0" xyz="-0.00374 0.0223 -0.0327" />
      <mass value="1.152" />
      <inertia 
        ixx="0.00584"
        ixy="-8.72E-05"
        ixz="-0.000289"
        iyy="0.0058"
        iyz="-0.000808"
        izz="0.00103" />
    </inertial>
  </link>
  <joint name="FR_calf_joint" type="revolute">
    <origin rpy="0 0 0" xyz="0 0 -0.213" />
    <parent link="FR_thigh" />
    <child link="FR_calf" />
    <axis xyz="0 1 0" />
    <dynamics damping="0" friction="0" />
    <limit effort="45.43" lower="-2.7227" upper="-0.83776" velocity="15.70" />
  </joint>
  <link name="FR_calf">
    <visual>
      <origin rpy="0 0 0" xyz="0 0 0" />
      <geometry>
        <mesh filename="../meshes/calf_mirror.dae"
          scale="1 1 1" />
      </geometry>
      <material name="orange" />
    </visual>
    <collision>
      <origin rpy="0 -0.2 0" xyz="0.01 0 -0.06" />
      <geometry>
        <cylinder length="0.12" radius="0.013" />
      </geometry>
    </collision>
    <inertial>
      <origin rpy="0 0 0" xyz="0.00548 0.000975 -0.115" />
      <mass value="0.154" />
      <inertia 
        ixx="0.00108"
        ixy="-3.4E-07"
        ixz="1.72E-05"
        iyy="0.0011"
        iyz="-8.28E-06"
        izz="3.29E-05" />
    </inertial>
  </link>
  <joint name="FR_foot_fixed" type="fixed" dont_collapse="true">
    <origin rpy="0 0 0" xyz="0 0 -0.213" />
    <parent link="FR_calf" />
    <child link="FR_foot" />
  </joint>
  <link name="FR_foot">
    <visual>
      <origin rpy="0 0 0" xyz="0 0 0" />
      <geometry>
        <mesh
          filename="../meshes/foot.dae" />
      </geometry>
      <material name="green" />
    </visual>
    <collision>
      <origin rpy="0 0 0" xyz="-0.002 0 0" />
      <geometry>
        <sphere radius="0.022" />
      </geometry>
    </collision>
    <inertial>
      <mass value="0.04" />
      <inertia 
        ixx="9.6e-06"
        ixy="0"
        ixz="0"
        iyy="9.6e-06"
        iyz="0"
        izz="9.6e-06" />
    </inertial>
  </link>
  <joint name="FL_hip_joint" type="revolute">
    <origin rpy="0 0 0" xyz="0.1934 0.0465 0" />
    <parent link="trunk" />
    <child link="FL_hip" />
    <axis xyz="1 0 0" />
    <dynamics damping="0" friction="0" />
    <limit effort="23.7" lower="-1.0472" upper="1.0472" velocity="30.1" />
  </joint>
  <link name="FL_hip">
    <visual>
      <origin rpy="0 0 0" xyz="0 0 0" />
      <geometry>
        <mesh filename="../meshes/hip.dae"
          scale="1 1 1" />
      </geometry>
      <material name="orange" />
    </visual>
    <!-- <collision>
      <origin rpy="1.5707963267948966 0 0" xyz="0 0.12675 0"/>
      <geometry>
        <cylinder length="0.04" radius="0.09"/>
      </geometry>
    </collision> -->
    <inertial>
      <origin rpy="0 0 0" xyz="-0.0054 0.00194 -0.000105" />
      <mass value="0.678" />
      <inertia 
        ixx="0.00048"
        ixy="-3.01E-06"
        ixz="1.11E-06"
        iyy="0.000884"
        iyz="-1.42E-06"
        izz="0.000596" />
    </inertial>
  </link>
  <joint name="FL_thigh_joint" type="revolute">
    <origin rpy="0 0 0" xyz="0 0.0955 0" />
    <parent link="FL_hip" />
    <child link="FL_thigh" />
    <axis xyz="0 1 0" />
    <dynamics damping="0" friction="0" />
    <limit effort="23.7" lower="-1.5708" upper="3.4907" velocity="30.1" />
  </joint>
  <link name="FL_thigh">
    <visual>
      <origin rpy="0 0 0" xyz="0 0 0" />
      <geometry>
        <mesh filename="../meshes/thigh.dae"
          scale="1 1 1" />
      </geometry>
      <material name="orange" />
    </visual>
    <collision>
      <origin rpy="0 1.5707963267948966 0" xyz="0 0 -0.1065" />
      <geometry>
        <box size="0.213 0.0245 0.034" />
      </geometry>
    </collision>
    <inertial>
      <origin rpy="0 0 0" xyz="-0.00374 -0.0223 -0.0327" />
      <mass value="1.152" />
      <inertia 
        ixx="0.00584"
        ixy="8.72E-05"
        ixz="-0.000289"
        iyy="0.0058"
        iyz="0.000808"
        izz="0.00103" />
    </inertial>
  </link>
  <joint name="FL_calf_joint" type="revolute">
    <origin rpy="0 0 0" xyz="0 0 -0.213" />
    <parent link="FL_thigh" />
    <child link="FL_calf" />
    <axis xyz="0 1 0" />
    <dynamics damping="0" friction="0" />
    <limit effort="45.43" lower="-2.7227" upper="-0.83776" velocity="15.70" />
  </joint>
  <link name="FL_calf">
    <visual>
      <origin rpy="0 0 0" xyz="0 0 0" />
      <geometry>
        <mesh filename="../meshes/calf.dae"
          scale="1 1 1" />
      </geometry>
      <material name="orange" />
    </visual>
    <collision>
      <origin rpy="0 -0.21 0" xyz="0.008 0 -0.06" />
      <geometry>
        <cylinder length="0.12" radius="0.012" />
      </geometry>
    </collision>
    <inertial>
      <origin rpy="0 0 0" xyz="0.00548 -0.000975 -0.115" />
      <mass value="0.154" />
      <inertia 
        ixx="0.00108"
        ixy="3.4E-07"
        ixz="1.72E-05"
        iyy="0.0011"
        iyz="8.28E-06"
        izz="3.29E-05" />
    </inertial>
  </link>
  <joint name="FL_foot_fixed" type="fixed" dont_collapse="true">
    <origin rpy="0 0 0" xyz="0 0 -0.213" />
    <parent link="FL_calf" />
    <child link="FL_foot" />
  </joint>
  <link name="FL_foot">
    <visual>
      <origin rpy="0 0 0" xyz="-0.002 0 0" />
      <geometry>
        <mesh
          filename="../meshes/foot.dae" />
      </geometry>
      <material name="green" />
    </visual>
    <collision>
      <origin rpy="0 0 0" xyz="-0.002 0 0" />
      <geometry>
        <sphere radius="0.022" />
      </geometry>
    </collision>
    <inertial>
      <mass value="0.04" />
      <inertia 
        ixx="9.6e-06"
        ixy="0"
        ixz="0"
        iyy="9.6e-06"
        iyz="0"
        izz="9.6e-06" />
    </inertial>
  </link>
  <joint name="RR_hip_joint" type="revolute">
    <origin rpy="0 0 0" xyz="-0.1934 -0.0465 0" />
    <parent link="trunk" />
    <child link="RR_hip" />
    <axis xyz="1 0 0" />
    <dynamics damping="0" friction="0" />
    <limit effort="23.7" lower="-1.0472" upper="1.0472" velocity="30.1" />
  </joint>
  <link name="RR_hip">
    <visual>
      <origin rpy="3.1415 3.1415 0" xyz="0 0 0" />
      <geometry>
        <mesh filename="../meshes/hip.dae"
          scale="1 1 1" />
      </geometry>
      <material name="orange" />
    </visual>
    <!-- <collision>
      <origin rpy="1.5707963267948966 0 0" xyz="0 -0.12675 0"/>
      <geometry>
        <cylinder length="0.04" radius="0.09"/>
      </geometry>
    </collision> -->
    <inertial>
      <origin rpy="0 0 0" xyz="0.0054 -0.00194 -0.000105" />
      <mass value="0.678" />
      <inertia 
        ixx="0.00048"
        ixy="-3.01E-06"
        ixz="-1.11E-06"
        iyy="0.000884"
        iyz="1.42E-06"
        izz="0.000596" />
    </inertial>
  </link>
  <joint name="RR_thigh_joint" type="revolute">
    <origin rpy="0 0 0" xyz="0 -0.0955 0" />
    <parent link="RR_hip" />
    <child link="RR_thigh" />
    <axis xyz="0 1 0" />
    <dynamics damping="0" friction="0" />
    <limit effort="23.7" lower="-0.5236" upper="4.5379" velocity="30.1" />
  </joint>
  <link name="RR_thigh">
    <visual>
      <origin rpy="0 0 0" xyz="0 0 0" />
      <geometry>
        <mesh
          filename="../meshes/thigh_mirror.dae"
          scale="1 1 1" />
      </geometry>
      <material name="orange" />
    </visual>
    <collision>
      <origin rpy="0 1.5707963267948966 0" xyz="0 0 -0.1065" />
      <geometry>
        <box size="0.213 0.0245 0.034" />
      </geometry>
    </collision>
    <inertial>
      <origin rpy="0 0 0" xyz="-0.00374 0.0223 -0.0327" />
      <mass value="1.152" />
      <inertia 
        ixx="0.00584"
        ixy="-8.72E-05"
        ixz="-0.000289"
        iyy="0.0058"
        iyz="-0.000808"
        izz="0.00103" />
    </inertial>
  </link>
  <joint name="RR_calf_joint" type="revolute">
    <origin rpy="0 0 0" xyz="0 0 -0.213" />
    <parent link="RR_thigh" />
    <child link="RR_calf" />
    <axis xyz="0 1 0" />
    <dynamics damping="0" friction="0" />
    <limit effort="45.43" lower="-2.7227" upper="-0.83776" velocity="15.70" />
  </joint>
  <link name="RR_calf">
    <visual>
      <origin rpy="0 0 0" xyz="0 0 0" />
      <geometry>
        <mesh filename="../meshes/calf_mirror.dae"
          scale="1 1 1" />
      </geometry>
      <material name="orange" />
    </visual>
    <collision>
      <origin rpy="0 -0.2 0" xyz="0.01 0 -0.06" />
      <geometry>
        <cylinder length="0.12" radius="0.013" />
      </geometry>
    </collision>
    <inertial>
      <origin rpy="0 0 0" xyz="0.00548 0.000975 -0.115" />
      <mass value="0.154" />
      <inertia 
        ixx="0.00108"
        ixy="-3.4E-07"
        ixz="1.72E-05"
        iyy="0.0011"
        iyz="-8.28E-06"
        izz="3.29E-05" />
    </inertial>
  </link>
  <joint name="RR_foot_fixed" type="fixed" dont_collapse="true">
    <origin rpy="0 0 0" xyz="0 0 -0.213" />
    <parent link="RR_calf" />
    <child link="RR_foot" />
  </joint>
  <link name="RR_foot">
    <visual>
      <origin rpy="0 0 0" xyz="0 0 0" />
      <geometry>
        <mesh
          filename="../meshes/foot.dae" />
      </geometry>
      <material name="green" />
    </visual>
    <collision>
      <origin rpy="0 0 0" xyz="-0.002 0 0" />
      <geometry>
        <sphere radius="0.022" />
      </geometry>
    </collision>
    <inertial>
      <mass value="0.04" />
      <inertia 
        ixx="9.6e-06"
        ixy="0"
        ixz="0"
        iyy="9.6e-06"
        iyz="0"
        izz="9.6e-06" />
    </inertial>
  </link>
  <joint name="RL_hip_joint" type="revolute">
    <origin rpy="0 0 0" xyz="-0.1934 0.0465 0" />
    <parent link="trunk" />
    <child link="RL_hip" />
    <axis xyz="1 0 0" />
    <dynamics damping="0" friction="0" />
    <limit effort="23.7" lower="-1.0472" upper="1.0472" velocity="30.1" />
  </joint>
  <link name="RL_hip">
    <visual>
      <origin rpy="0 3.1415 0" xyz="0 0 0" />
      <geometry>
        <mesh filename="../meshes/hip.dae"
          scale="1 1 1" />
      </geometry>
      <material name="orange" />
    </visual>
    <!-- <collision>
      <origin rpy="1.5707963267948966 0 0" xyz="0 0.12675 0"/>
      <geometry>
        <cylinder length="0.04" radius="0.09"/>
      </geometry>
    </collision> -->
    <inertial>
      <origin rpy="0 0 0" xyz="0.0054 0.00194 -0.000105" />
      <mass value="0.678" />
      <inertia 
        ixx="0.00048"
        ixy="3.01E-06"
        ixz="-1.11E-06"
        iyy="0.000884"
        iyz="-1.42E-06"
        izz="0.000596" />
    </inertial>
  </link>
  <joint name="RL_thigh_joint" type="revolute">
    <origin rpy="0 0 0" xyz="0 0.0955 0" />
    <parent link="RL_hip" />
    <child link="RL_thigh" />
    <axis xyz="0 1 0" />
    <dynamics damping="0" friction="0" />
    <limit effort="23.7" lower="-0.5236" upper="4.5379" velocity="30.1" />
  </joint>
  <link name="RL_thigh">
    <visual>
      <origin rpy="0 0 0" xyz="0 0 0" />
      <geometry>
        <mesh filename="../meshes/thigh.dae"
          scale="1 1 1" />
      </geometry>
      <material name="orange" />
    </visual>
    <collision>
      <origin rpy="0 1.5707963267948966 0" xyz="0 0 -0.1065" />
      <geometry>
        <box size="0.213 0.0245 0.034" />
      </geometry>
    </collision>
    <inertial>
      <origin rpy="0 0 0" xyz="-0.00374 -0.0223 -0.0327" />
      <mass value="1.152" />
      <inertia 
        ixx="0.00584"
        ixy="8.72E-05"
        ixz="-0.000289"
        iyy="0.0058"
        iyz="0.000808"
        izz="0.00103" />
    </inertial>
  </link>
  <joint name="RL_calf_joint" type="revolute">
    <origin rpy="0 0 0" xyz="0 0 -0.213" />
    <parent link="RL_thigh" />
    <child link="RL_calf" />
    <axis xyz="0 1 0" />
    <dynamics damping="0" friction="0" />
    <limit effort="45.43" lower="-2.7227" upper="-0.83776" velocity="15.70" />
  </joint>
  <link name="RL_calf">
    <visual>
      <origin rpy="0 0 0" xyz="0 0 0" />
      <geometry>
        <mesh filename="../meshes/calf.dae"
          scale="1 1 1" />
      </geometry>
      <material name="orange" />
    </visual>
    <collision>
      <origin rpy="0 -0.2 0" xyz="0.01 0 -0.06" />
      <geometry>
        <cylinder length="0.12" radius="0.013" />
      </geometry>
    </collision>
    <inertial>
      <origin rpy="0 0 0" xyz="0.00548 -0.000975 -0.115" />
      <mass value="0.154" />
      <inertia 
        ixx="0.00108"
        ixy="3.4E-07"
        ixz="1.72E-05"
        iyy="0.0011"
        iyz="8.28E-06"
        izz="3.29E-05" />
    </inertial>
  </link>
  <joint name="RL_foot_fixed" type="fixed" dont_collapse="true">
    <origin rpy="0 0 0" xyz="0 0 -0.213" />
    <parent link="RL_calf" />
    <child link="RL_foot" />
  </joint>
  <link name="RL_foot">
    <visual>
      <origin rpy="0 0 0" xyz="0 0 0" />
      <geometry>
        <mesh
          filename="../meshes/foot.dae" />
      </geometry>
      <material name="green" />
    </visual>
    <collision>
      <origin rpy="0 0 0" xyz="-0.002 0 0" />
      <geometry>
        <sphere radius="0.022" />
      </geometry>
    </collision>
    <inertial>
      <mass value="0.04" />
      <inertia 
        ixx="9.6e-06"
        ixy="0"
        ixz="0"
        iyy="9.6e-06"
        iyz="0"
        izz="9.6e-06" />
    </inertial>
  </link>
  <!-- End of Go2 Links and Joints -->

  <!-- Start of D1 Links and Joints -->
  <joint name="base_static_joint" type="fixed">
    <origin rpy="0 0 0" xyz="0 0 0.05" />
    <parent link="base" />
    <child link="link00" />
  </joint>  
  <link name="link00">
    <visual>
      <origin rpy="-1.571 0 0" xyz="0 0 0" />
      <geometry>
        <mesh filename="../meshes/d1_Link00.dae"
          scale="1 1 1" />
      </geometry>
    </visual>
    <collision>
      <geometry>
        <mesh filename="../meshes/d1_Link00.dae" />
      </geometry>
      <origin rpy="0 0 0" xyz="0 0 0" />
    </collision>
    <inertial>
      <origin rpy="0 0 0" xyz="-0.0019964 -0.00011691 0.027447" />
      <mass value="0.16166" />
      <inertia 
        ixx="8.6547E-05"
        ixy="-5.5665E-08"
        ixz="-1.2705E-07"
        iyy="7.3583E-05"
        iyz="3.5719E-07"
        izz="8.2287E-05" />
    </inertial>
  </link>
  <joint name="d1_waist" type="revolute">
    <origin rpy="0 0 0" xyz="-2.5E-05 0 0.0508" />
    <parent link="link00" />
    <child link="link01" />
    <axis xyz="0 0 1" />
    <dynamics damping="1.0" friction="1.0" />
    <limit effort="30" lower="-2.35" upper="2.35" velocity="10" />
  </joint>
  <link name="link01">
    <visual>
      <origin rpy="1.5707963267948966 0 0" xyz="0 0 0" />
      <geometry>
        <mesh filename="../meshes/z1_Link01.dae"
          scale="1 1 1" />
      </geometry>
    </visual>
    <!-- <collision>
            <geometry>
                <cylinder length="${2*motor_height}" radius="${motor_diameter}"/>
            </geometry>
            <origin rpy="0 0 0" xyz="0 0 0"/>
        </collision> -->
    <inertial>
      <origin rpy="0 0 0" xyz="0.0002018 0.19201 -0.027407" />
      <mass value="0.67332551" />
      <inertia ixx="0.00128328" ixy="6e-08" ixz="4e-07" iyy="0.00071931" iyz="-5e-07"
        izz="0.00083936" />
    </inertial>
  </link>
</robot>